"""
Which of the following code lines is the correct one if we want to break out of the while loop?

flowers = ['roses', 'daisies', 'dahlias', 'camellias']
i = 0
while True:
    try:
        print(flowers[i])
        i += 1
    ... :
        break

except IndexError

What happens when an exception branch is executed?

No other branch after or before that is executed.

When does the unnamed exception run?
when there is no dedicated named exception
when it is the only exception branch









"""
